Workbook

Sheet Read Me
A1: version 2: | B1: Original a(CDOM) values have been replaced with extrapolated CDOM values.
B2: The a(CDOM) plots with original a(CDOM) values were not smooth and had lots of outliers.
B3: Therefore, it was choosen to compute the "S", by plotting wavelength vs. LN(a(CDOM)) and extrapolate the a(CDOM) values on the basis of the S value at other wavelengths from a(CDOM) at 440 nm.

Sheet a(w)
A1: a(w)
B2: WMS_04 | C2: WMS_05 | D2: WMS_06 | E2: WMS_07 | F2: WMS_09 | G2: WMS_13 | H2: WMS_14 | I2: WMS_15 | J2: WMS_16 | K2: WMS_17 | L2: WMS_18 | M2: WMS_19 | N2: WMS_20 | O2: WMS_22 | P2: WMS_23 | Q2: WMS_24 | R2: WMS_25 | S2: WMS_26 | T2: WMS_27 | U2: WMS_29 | V2: WMS_30 | W2: WMS_31 | X2: WMS_32 | Y2: WMS_33 | Z2: WMS_34 | AA2: WMS_35 | AB2: WMS_36 | AC2: WMS_37 | AD2: WMS_38 | AE2: WMS_39
A3: 400 | B3: 0.00663 | C3: 0.00663 | D3: 0.00663 | E3: 0.00663 | F3: 0.00663 | G3: 0.00663 | H3: 0.00663 | I3: 0.00663 | J3: 0.00663 | K3: 0.00663 | L3: 0.00663 | M3: 0.00663 | N3: 0.00663 | O3: 0.00663 | P3: 0.00663 | Q3: 0.00663 | R3: 0.00663 | S3: 0.00663 | T3: 0.00663 | U3: 0.00663 | V3: 0.00663 | W3: 0.00663 | X3: 0.00663 | Y3: 0.00663 | Z3: 0.00663 | AA3: 0.00663 | AB3: 0.00663 | AC3: 0.00663 | AD3: 0.00663 | AE3: 0.00663
A4: 401 | B4: 0.006364 | C4: 0.006364 | D4: 0.006364 | E4: 0.006364 | F4: 0.006364 | G4: 0.006364 | H4: 0.006364 | I4: 0.006364 | J4: 0.006364 | K4: 0.006364 | L4: 0.006364 | M4: 0.006364 | N4: 0.006364 | O4: 0.006364 | P4: 0.006364 | Q4: 0.006364 | R4: 0.006364 | S4: 0.006364 | T4: 0.006364 | U4: 0.006364 | V4: 0.006364 | W4: 0.006364 | X4: 0.006364 | Y4: 0.006364 | Z4: 0.006364 | AA4: 0.006364 | AB4: 0.006364 | AC4: 0.006364 | AD4: 0.006364 | AE4: 0.006364
A5: 402 | B5: 0.006098 | C5: 0.006098 | D5: 0.006098 | E5: 0.006098 | F5: 0.006098 | G5: 0.006098 | H5: 0.006098 | I5: 0.006098 | J5: 0.006098 | K5: 0.006098 | L5: 0.006098 | M5: 0.006098 | N5: 0.006098 | O5: 0.006098 | P5: 0.006098 | Q5: 0.006098 | R5: 0.006098 | S5: 0.006098 | T5: 0.006098 | U5: 0.006098 | V5: 0.006098 | W5: 0.006098 | X5: 0.006098 | Y5: 0.006098 | Z5: 0.006098 | AA5: 0.006098 | AB5: 0.006098 | AC5: 0.006098 | AD5: 0.006098 | AE5: 0.006098
A6: 403 | B6: 0.005832 | C6: 0.005832 | D6: 0.005832 | E6: 0.005832 | F6: 0.005832 | G6: 0.005832 | H6: 0.005832 | I6: 0.005832 | J6: 0.005832 | K6: 0.005832 | L6: 0.005832 | M6: 0.005832 | N6: 0.005832 | O6: 0.005832 | P6: 0.005832 | Q6: 0.005832 | R6: 0.005832 | S6: 0.005832 | T6: 0.005832 | U6: 0.005832 | V6: 0.005832 | W6: 0.005832 | X6: 0.005832 | Y6: 0.005832 | Z6: 0.005832 | AA6: 0.005832 | AB6: 0.005832 | AC6: 0.005832 | AD6: 0.005832 | AE6: 0.005832
A7: 404 | B7: 0.005566 | C7: 0.005566 | D7: 0.005566 | E7: 0.005566 | F7: 0.005566 | G7: 0.005566 | H7: 0.005566 | I7: 0.005566 | J7: 0.005566 | K7: 0.005566 | L7: 0.005566 | M7: 0.005566 | N7: 0.005566 | O7: 0.005566 | P7: 0.005566 | Q7: 0.005566 | R7: 0.005566 | S7: 0.005566 | T7: 0.005566 | U7: 0.005566 | V7: 0.005566 | W7: 0.005566 | X7: 0.005566 | Y7: 0.005566 | Z7: 0.005566 | AA7: 0.005566 | AB7: 0.005566 | AC7: 0.005566 | AD7: 0.005566 | AE7: 0.005566
A8: 405 | B8: 0.0053 | C8: 0.0053 | D8: 0.0053 | E8: 0.0053 | F8: 0.0053 | G8: 0.0053 | H8: 0.0053 | I8: 0.0053 | J8: 0.0053 | K8: 0.0053 | L8: 0.0053 | M8: 0.0053 | N8: 0.0053 | O8: 0.0053 | P8: 0.0053 | Q8: 0.0053 | R8: 0.0053 | S8: 0.0053 | T8: 0.0053 | U8: 0.0053 | V8: 0.0053 | W8: 0.0053 | X8: 0.0053 | Y8: 0.0053 | Z8: 0.0053 | AA8: 0.0053 | AB8: 0.0053 | AC8: 0.0053 | AD8: 0.0053 | AE8: 0.0053
A9: 406 | B9: 0.005186 | C9: 0.005186 | D9: 0.005186 | E9: 0.005186 | F9: 0.005186 | G9: 0.005186 | H9: 0.005186 | I9: 0.005186 | J9: 0.005186 | K9: 0.005186 | L9: 0.005186 | M9: 0.005186 | N9: 0.005186 | O9: 0.005186 | P9: 0.005186 | Q9: 0.005186 | R9: 0.005186 | S9: 0.005186 | T9: 0.005186 | U9: 0.005186 | V9: 0.005186 | W9: 0.005186 | X9: 0.005186 | Y9: 0.005186 | Z9: 0.005186 | AA9: 0.005186 | AB9: 0.005186 | AC9: 0.005186 | AD9: 0.005186 | AE9: 0.005186
A10: 407 | B10: 0.005072 | C10: 0.005072 | D10: 0.005072 | E10: 0.005072 | F10: 0.005072 | G10: 0.005072 | H10: 0.005072 | I10: 0.005072 | J10: 0.005072 | K10: 0.005072 | L10: 0.005072 | M10: 0.005072 | N10: 0.005072 | O10: 0.005072 | P10: 0.005072 | Q10: 0.005072 | R10: 0.005072 | S10: 0.005072 | T10: 0.005072 | U10: 0.005072 | V10: 0.005072 | W10: 0.005072 | X10: 0.005072 | Y10: 0.005072 | Z10: 0.005072 | AA10: 0.005072 | AB10: 0.005072 | AC10: 0.005072 | AD10: 0.005072 | AE10: 0.005072
A11: 408 | B11: 0.004958 | C11: 0.004958 | D11: 0.004958 | E11: 0.004958 | F11: 0.004958 | G11: 0.004958 | H11: 0.004958 | I11: 0.004958 | J11: 0.004958 | K11: 0.004958 | L11: 0.004958 | M11: 0.004958 | N11: 0.004958 | O11: 0.004958 | P11: 0.004958 | Q11: 0.004958 | R11: 0.004958 | S11: 0.004958 | T11: 0.004958 | U11: 0.004958 | V11: 0.004958 | W11: 0.004958 | X11: 0.004958 | Y11: 0.004958 | Z11: 0.004958 | AA11: 0.004958 | AB11: 0.004958 | AC11: 0.004958 | AD11: 0.004958 | AE11: 0.004958
A12: 409 | B12: 0.004844 | C12: 0.004844 | D12: 0.004844 | E12: 0.004844 | F12: 0.004844 | G12: 0.004844 | H12: 0.004844 | I12: 0.004844 | J12: 0.004844 | K12: 0.004844 | L12: 0.004844 | M12: 0.004844 | N12: 0.004844 | O12: 0.004844 | P12: 0.004844 | Q12: 0.004844 | R12: 0.004844 | S12: 0.004844 | T12: 0.004844 | U12: 0.004844 | V12: 0.004844 | W12: 0.004844 | X12: 0.004844 | Y12: 0.004844 | Z12: 0.004844 | AA12: 0.004844 | AB12: 0.004844 | AC12: 0.004844 | AD12: 0.004844 | AE12: 0.004844
A13: 410 | B13: 0.00473 | C13: 0.00473 | D13: 0.00473 | E13: 0.00473 | F13: 0.00473 | G13: 0.00473 | H13: 0.00473 | I13: 0.00473 | J13: 0.00473 | K13: 0.00473 | L13: 0.00473 | M13: 0.00473 | N13: 0.00473 | O13: 0.00473 | P13: 0.00473 | Q13: 0.00473 | R13: 0.00473 | S13: 0.00473 | T13: 0.00473 | U13: 0.00473 | V13: 0.00473 | W13: 0.00473 | X13: 0.00473 | Y13: 0.00473 | Z13: 0.00473 | AA13: 0.00473 | AB13: 0.00473 | AC13: 0.00473 | AD13: 0.00473 | AE13: 0.00473
A14: 411 | B14: 0.004672 | C14: 0.004672 | D14: 0.004672 | E14: 0.004672 | F14: 0.004672 | G14: 0.004672 | H14: 0.004672 | I14: 0.004672 | J14: 0.004672 | K14: 0.004672 | L14: 0.004672 | M14: 0.004672 | N14: 0.004672 | O14: 0.004672 | P14: 0.004672 | Q14: 0.004672 | R14: 0.004672 | S14: 0.004672 | T14: 0.004672 | U14: 0.004672 | V14: 0.004672 | W14: 0.004672 | X14: 0.004672 | Y14: 0.004672 | Z14: 0.004672 | AA14: 0.004672 | AB14: 0.004672 | AC14: 0.004672 | AD14: 0.004672 | AE14: 0.004672
... A603: 1000 | B603: 40.715041 | C603: 40.715041 | D603: 40.715041 | E603: 40.715041 | F603: 40.715041 | G603: 40.715041 | H603: 40.715041 | I603: 40.715041 | J603: 40.715041 | K603: 40.715041 | L603: 40.715041 | M603: 40.715041 | N603: 40.715041 | O603: 40.715041 | P603: 40.715041 | Q603: 40.715041 | R603: 40.715041 | S603: 40.715041 | T603: 40.715041 | U603: 40.715041 | V603: 40.715041 | W603: 40.715041 | X603: 40.715041 | Y603: 40.715041 | Z603: 40.715041 | AA603: 40.715041 | AB603: 40.715041 | AC603: 40.715041 | AD603: 40.715041 | AE603: 40.715041

Sheet bb(w)
A2: Wavelength | B2: WMS_04 | C2: WMS_05 | D2: WMS_06 | E2: WMS_07 | F2: WMS_09 | G2: WMS_13 | H2: WMS_14 | I2: WMS_15 | J2: WMS_16 | K2: WMS_17 | L2: WMS_18 | M2: WMS_19 | N2: WMS_20 | O2: WMS_22 | P2: WMS_23 | Q2: WMS_24 | R2: WMS_25 | S2: WMS_26 | T2: WMS_27 | U2: WMS_29 | V2: WMS_30 | W2: WMS_31 | X2: WMS_32 | Y2: WMS_33 | Z2: WMS_34 | AA2: WMS_35 | AB2: WMS_36 | AC2: WMS_37 | AD2: WMS_38 | AE2: WMS_39
A3: 400 | B3: 0.003774735 | C3: 0.003774735 | D3: 0.003774735 | E3: 0.003774735 | F3: 0.003774735 | G3: 0.003774735 | H3: 0.003774735 | I3: 0.003774735 | J3: 0.003774735 | K3: 0.003774735 | L3: 0.003774735 | M3: 0.003774735 | N3: 0.003774735 | O3: 0.003774735 | P3: 0.003774735 | Q3: 0.003774735 | R3: 0.003774735 | S3: 0.003774735 | T3: 0.003774735 | U3: 0.003774735 | V3: 0.003774735 | W3: 0.003774735 | X3: 0.003774735 | Y3: 0.003774735 | Z3: 0.003774735 | AA3: 0.003774735 | AB3: 0.003774735 | AC3: 0.003774735 | AD3: 0.003774735 | AE3: 0.003774735
A4: 401 | B4: 0.00373449 | C4: 0.00373449 | D4: 0.00373449 | E4: 0.00373449 | F4: 0.00373449 | G4: 0.00373449 | H4: 0.00373449 | I4: 0.00373449 | J4: 0.00373449 | K4: 0.00373449 | L4: 0.00373449 | M4: 0.00373449 | N4: 0.00373449 | O4: 0.00373449 | P4: 0.00373449 | Q4: 0.00373449 | R4: 0.00373449 | S4: 0.00373449 | T4: 0.00373449 | U4: 0.00373449 | V4: 0.00373449 | W4: 0.00373449 | X4: 0.00373449 | Y4: 0.00373449 | Z4: 0.00373449 | AA4: 0.00373449 | AB4: 0.00373449 | AC4: 0.00373449 | AD4: 0.00373449 | AE4: 0.00373449
A5: 402 | B5: 0.00369477 | C5: 0.00369477 | D5: 0.00369477 | E5: 0.00369477 | F5: 0.00369477 | G5: 0.00369477 | H5: 0.00369477 | I5: 0.00369477 | J5: 0.00369477 | K5: 0.00369477 | L5: 0.00369477 | M5: 0.00369477 | N5: 0.00369477 | O5: 0.00369477 | P5: 0.00369477 | Q5: 0.00369477 | R5: 0.00369477 | S5: 0.00369477 | T5: 0.00369477 | U5: 0.00369477 | V5: 0.00369477 | W5: 0.00369477 | X5: 0.00369477 | Y5: 0.00369477 | Z5: 0.00369477 | AA5: 0.00369477 | AB5: 0.00369477 | AC5: 0.00369477 | AD5: 0.00369477 | AE5: 0.00369477
A6: 403 | B6: 0.00365558 | C6: 0.00365558 | D6: 0.00365558 | E6: 0.00365558 | F6: 0.00365558 | G6: 0.00365558 | H6: 0.00365558 | I6: 0.00365558 | J6: 0.00365558 | K6: 0.00365558 | L6: 0.00365558 | M6: 0.00365558 | N6: 0.00365558 | O6: 0.00365558 | P6: 0.00365558 | Q6: 0.00365558 | R6: 0.00365558 | S6: 0.00365558 | T6: 0.00365558 | U6: 0.00365558 | V6: 0.00365558 | W6: 0.00365558 | X6: 0.00365558 | Y6: 0.00365558 | Z6: 0.00365558 | AA6: 0.00365558 | AB6: 0.00365558 | AC6: 0.00365558 | AD6: 0.00365558 | AE6: 0.00365558
A7: 404 | B7: 0.0036169 | C7: 0.0036169 | D7: 0.0036169 | E7: 0.0036169 | F7: 0.0036169 | G7: 0.0036169 | H7: 0.0036169 | I7: 0.0036169 | J7: 0.0036169 | K7: 0.0036169 | L7: 0.0036169 | M7: 0.0036169 | N7: 0.0036169 | O7: 0.0036169 | P7: 0.0036169 | Q7: 0.0036169 | R7: 0.0036169 | S7: 0.0036169 | T7: 0.0036169 | U7: 0.0036169 | V7: 0.0036169 | W7: 0.0036169 | X7: 0.0036169 | Y7: 0.0036169 | Z7: 0.0036169 | AA7: 0.0036169 | AB7: 0.0036169 | AC7: 0.0036169 | AD7: 0.0036169 | AE7: 0.0036169
A8: 405 | B8: 0.00357872 | C8: 0.00357872 | D8: 0.00357872 | E8: 0.00357872 | F8: 0.00357872 | G8: 0.00357872 | H8: 0.00357872 | I8: 0.00357872 | J8: 0.00357872 | K8: 0.00357872 | L8: 0.00357872 | M8: 0.00357872 | N8: 0.00357872 | O8: 0.00357872 | P8: 0.00357872 | Q8: 0.00357872 | R8: 0.00357872 | S8: 0.00357872 | T8: 0.00357872 | U8: 0.00357872 | V8: 0.00357872 | W8: 0.00357872 | X8: 0.00357872 | Y8: 0.00357872 | Z8: 0.00357872 | AA8: 0.00357872 | AB8: 0.00357872 | AC8: 0.00357872 | AD8: 0.00357872 | AE8: 0.00357872
A9: 406 | B9: 0.00354104 | C9: 0.00354104 | D9: 0.00354104 | E9: 0.00354104 | F9: 0.00354104 | G9: 0.00354104 | H9: 0.00354104 | I9: 0.00354104 | J9: 0.00354104 | K9: 0.00354104 | L9: 0.00354104 | M9: 0.00354104 | N9: 0.00354104 | O9: 0.00354104 | P9: 0.00354104 | Q9: 0.00354104 | R9: 0.00354104 | S9: 0.00354104 | T9: 0.00354104 | U9: 0.00354104 | V9: 0.00354104 | W9: 0.00354104 | X9: 0.00354104 | Y9: 0.00354104 | Z9: 0.00354104 | AA9: 0.00354104 | AB9: 0.00354104 | AC9: 0.00354104 | AD9: 0.00354104 | AE9: 0.00354104
A10: 407 | B10: 0.00350385 | C10: 0.00350385 | D10: 0.00350385 | E10: 0.00350385 | F10: 0.00350385 | G10: 0.00350385 | H10: 0.00350385 | I10: 0.00350385 | J10: 0.00350385 | K10: 0.00350385 | L10: 0.00350385 | M10: 0.00350385 | N10: 0.00350385 | O10: 0.00350385 | P10: 0.00350385 | Q10: 0.00350385 | R10: 0.00350385 | S10: 0.00350385 | T10: 0.00350385 | U10: 0.00350385 | V10: 0.00350385 | W10: 0.00350385 | X10: 0.00350385 | Y10: 0.00350385 | Z10: 0.00350385 | AA10: 0.00350385 | AB10: 0.00350385 | AC10: 0.00350385 | AD10: 0.00350385 | AE10: 0.00350385
A11: 408 | B11: 0.00346715 | C11: 0.00346715 | D11: 0.00346715 | E11: 0.00346715 | F11: 0.00346715 | G11: 0.00346715 | H11: 0.00346715 | I11: 0.00346715 | J11: 0.00346715 | K11: 0.00346715 | L11: 0.00346715 | M11: 0.00346715 | N11: 0.00346715 | O11: 0.00346715 | P11: 0.00346715 | Q11: 0.00346715 | R11: 0.00346715 | S11: 0.00346715 | T11: 0.00346715 | U11: 0.00346715 | V11: 0.00346715 | W11: 0.00346715 | X11: 0.00346715 | Y11: 0.00346715 | Z11: 0.00346715 | AA11: 0.00346715 | AB11: 0.00346715 | AC11: 0.00346715 | AD11: 0.00346715 | AE11: 0.00346715
A12: 409 | B12: 0.003430915 | C12: 0.003430915 | D12: 0.003430915 | E12: 0.003430915 | F12: 0.003430915 | G12: 0.003430915 | H12: 0.003430915 | I12: 0.003430915 | J12: 0.003430915 | K12: 0.003430915 | L12: 0.003430915 | M12: 0.003430915 | N12: 0.003430915 | O12: 0.003430915 | P12: 0.003430915 | Q12: 0.003430915 | R12: 0.003430915 | S12: 0.003430915 | T12: 0.003430915 | U12: 0.003430915 | V12: 0.003430915 | W12: 0.003430915 | X12: 0.003430915 | Y12: 0.003430915 | Z12: 0.003430915 | AA12: 0.003430915 | AB12: 0.003430915 | AC12: 0.003430915 | AD12: 0.003430915 | AE12: 0.003430915
A13: 410 | B13: 0.00339515 | C13: 0.00339515 | D13: 0.00339515 | E13: 0.00339515 | F13: 0.00339515 | G13: 0.00339515 | H13: 0.00339515 | I13: 0.00339515 | J13: 0.00339515 | K13: 0.00339515 | L13: 0.00339515 | M13: 0.00339515 | N13: 0.00339515 | O13: 0.00339515 | P13: 0.00339515 | Q13: 0.00339515 | R13: 0.00339515 | S13: 0.00339515 | T13: 0.00339515 | U13: 0.00339515 | V13: 0.00339515 | W13: 0.00339515 | X13: 0.00339515 | Y13: 0.00339515 | Z13: 0.00339515 | AA13: 0.00339515 | AB13: 0.00339515 | AC13: 0.00339515 | AD13: 0.00339515 | AE13: 0.00339515
A14: 411 | B14: 0.003359845 | C14: 0.003359845 | D14: 0.003359845 | E14: 0.003359845 | F14: 0.003359845 | G14: 0.003359845 | H14: 0.003359845 | I14: 0.003359845 | J14: 0.003359845 | K14: 0.003359845 | L14: 0.003359845 | M14: 0.003359845 | N14: 0.003359845 | O14: 0.003359845 | P14: 0.003359845 | Q14: 0.003359845 | R14: 0.003359845 | S14: 0.003359845 | T14: 0.003359845 | U14: 0.003359845 | V14: 0.003359845 | W14: 0.003359845 | X14: 0.003359845 | Y14: 0.003359845 | Z14: 0.003359845 | AA14: 0.003359845 | AB14: 0.003359845 | AC14: 0.003359845 | AD14: 0.003359845 | AE14: 0.003359845
... A603: 1000 | B603: 7.6588e-05 | C603: 7.6588e-05 | D603: 7.6588e-05 | E603: 7.6588e-05 | F603: 7.6588e-05 | G603: 7.6588e-05 | H603: 7.6588e-05 | I603: 7.6588e-05 | J603: 7.6588e-05 | K603: 7.6588e-05 | L603: 7.6588e-05 | M603: 7.6588e-05 | N603: 7.6588e-05 | O603: 7.6588e-05 | P603: 7.6588e-05 | Q603: 7.6588e-05 | R603: 7.6588e-05 | S603: 7.6588e-05 | T603: 7.6588e-05 | U603: 7.6588e-05 | V603: 7.6588e-05 | W603: 7.6588e-05 | X603: 7.6588e-05 | Y603: 7.6588e-05 | Z603: 7.6588e-05 | AA603: 7.6588e-05 | AB603: 7.6588e-05 | AC603: 7.6588e-05 | AD603: 7.6588e-05 | AE603: 7.6588e-05

Sheet a(CDOM)
A2: Wavelength | B2: WMS_04 | C2: WMS_05 | D2: WMS_06 | E2: WMS_07 | F2: WMS_09 | G2: WMS_13 | H2: WMS_14 | I2: WMS_15 | J2: WMS_16 | K2: WMS_17 | L2: WMS_18 | M2: WMS_19 | N2: WMS_20 | O2: WMS_22 | P2: WMS_23 | Q2: WMS_24 | R2: WMS_25 | S2: WMS_26 | T2: WMS_27 | U2: WMS_29 | V2: WMS_30 | W2: WMS_31 | X2: WMS_32 | Y2: WMS_33 | Z2: WMS_34 | AA2: WMS_35 | AB2: WMS_36 | AC2: WMS_37 | AD2: WMS_38 | AE2: WMS_39
A3: 400 | B3: 0.016713997 | C3: 0.018266856 | D3: 0.033684456 | E3: 0.017185021 | F3: 0.015679978 | G3: 0.018162504 | H3: 0.018162504 | I3: 0.017007255 | J3: 0.017291544 | K3: 0.025735752 | L3: 0.021981592 | M3: 0.021813374 | N3: 0.015479765 | O3: 0.014745488 | P3: 0.024840064 | Q3: 0.011191539 | R3: 0.016874815 | S3: 0.017508137 | T3: 0.024234795 | U3: 0.016975438 | V3: 0.031510172 | W3: 0.013183748 | X3: 0.018617366 | Y3: 0.010604894 | Z3: 0.014127041 | AA3: 0.01005978 | AB3: 0.0095931355 | AC3: 0.0080892125 | AD3: 0.0091967831 | AE3: 0.010995607
A4: 401 | B4: 0.016491524 | C4: 0.018072443 | D4: 0.0334997 | E4: 0.016935942 | F4: 0.015461988 | G4: 0.017978188 | H4: 0.017978188 | I4: 0.016792628 | J4: 0.017080161 | K4: 0.025494969 | L4: 0.021717218 | M4: 0.021561801 | N4: 0.015264558 | O4: 0.014557949 | P4: 0.024637208 | Q4: 0.011009494 | R4: 0.016708579 | S4: 0.017326996 | T4: 0.024012858 | U4: 0.01675116 | V4: 0.031265348 | W4: 0.013025186 | X4: 0.018443183 | Y4: 0.01042822 | Z4: 0.013957134 | AA4: 0.0098724224 | AB4: 0.0094314306 | AC4: 0.007952063 | AD4: 0.0090291096 | AE4: 0.010799456
A5: 402 | B5: 0.016272011 | C5: 0.017880099 | D5: 0.033315957 | E5: 0.016690474 | F5: 0.015247028 | G5: 0.017795743 | H5: 0.017795743 | I5: 0.016580711 | J5: 0.016871361 | K5: 0.025256439 | L5: 0.021456023 | M5: 0.021313129 | N5: 0.015052343 | O5: 0.014372795 | P5: 0.024436009 | Q5: 0.010830411 | R5: 0.01654398 | S5: 0.017147729 | T5: 0.023792952 | U5: 0.016529844 | V5: 0.031022427 | W5: 0.012868531 | X5: 0.01827063 | Y5: 0.010254489 | Z5: 0.01378927 | AA5: 0.0096885546 | AB5: 0.0092724514 | AC5: 0.0078172387 | AD5: 0.0088644931 | AE5: 0.010606805
A6: 403 | B6: 0.016055421 | C6: 0.017689802 | D6: 0.033133223 | E6: 0.016448563 | F6: 0.015035057 | G6: 0.017615149 | H6: 0.017615149 | I6: 0.016371467 | J6: 0.016665115 | K6: 0.025020141 | L6: 0.021197969 | M6: 0.021067325 | N6: 0.014843078 | O6: 0.014189995 | P6: 0.024236453 | Q6: 0.010654241 | R6: 0.016381003 | S6: 0.016970317 | T6: 0.023575061 | U6: 0.016311453 | V6: 0.030781394 | W6: 0.01271376 | X6: 0.01809969 | Y6: 0.010083653 | Z6: 0.013623425 | AA6: 0.0095081113 | AB6: 0.009116152 | AC6: 0.0076847004 | AD6: 0.0087028779 | AE6: 0.010417591
A7: 404 | B7: 0.015841713 | C7: 0.01750153 | D7: 0.03295149 | E7: 0.016210159 | F7: 0.014826033 | G7: 0.017436388 | H7: 0.017436388 | I7: 0.016164864 | J7: 0.016461389 | K7: 0.024786054 | L7: 0.020943019 | M7: 0.020824356 | N7: 0.014636723 | O7: 0.014009521 | P7: 0.024038527 | Q7: 0.010480936 | R7: 0.016219631 | S7: 0.01679474 | T7: 0.023359165 | U7: 0.016095947 | V7: 0.030542233 | W7: 0.012560851 | X7: 0.01793035 | Y7: 0.0099156624 | Z7: 0.013459575 | AA7: 0.0093310286 | AB7: 0.0089624873 | AC7: 0.0075544091 | AD7: 0.0085442091 | AE7: 0.010231752
A8: 405 | B8: 0.01563085 | C8: 0.017315262 | D8: 0.032770754 | E8: 0.01597521 | F8: 0.014619914 | G8: 0.017259441 | H8: 0.017259441 | I8: 0.015960868 | J8: 0.016260154 | K8: 0.024554157 | L8: 0.020691136 | M8: 0.020584189 | N8: 0.014433237 | O8: 0.013831342 | P8: 0.023842217 | Q8: 0.010310451 | R8: 0.016059849 | S8: 0.01662098 | T8: 0.023145246 | U8: 0.015883288 | V8: 0.03030493 | W8: 0.01240978 | X8: 0.017762595 | Y8: 0.0097504708 | Z8: 0.013297696 | AA8: 0.0091572439 | AB8: 0.0088114128 | AC8: 0.007426327 | AD8: 0.0083884332 | AE8: 0.010049228
A9: 406 | B9: 0.015422794 | C9: 0.017130976 | D9: 0.03259101 | E9: 0.015743666 | F9: 0.014416662 | G9: 0.017084289 | H9: 0.017084289 | I9: 0.015759447 | J9: 0.016061379 | K9: 0.024324429 | L9: 0.020442282 | M9: 0.020346792 | N9: 0.014232579 | O9: 0.013655429 | P9: 0.02364751 | Q9: 0.010142738 | R9: 0.015901641 | S9: 0.016449018 | T9: 0.022933287 | U9: 0.015673439 | V9: 0.030069471 | W9: 0.012260527 | X9: 0.017596409 | Y9: 0.0095880312 | Z9: 0.013137763 | AA9: 0.0089866959 | AB9: 0.0086628848 | AC9: 0.0073004164 | AD9: 0.0082354974 | AE9: 0.00986996
A10: 407 | B10: 0.015217507 | C10: 0.016948652 | D10: 0.032412251 | E10: 0.015515478 | F10: 0.014216235 | G10: 0.016910915 | H10: 0.016910915 | I10: 0.015560568 | J10: 0.015865034 | K10: 0.024096851 | L10: 0.02019642 | M10: 0.020112133 | N10: 0.014034712 | O10: 0.013481753 | P10: 0.023454394 | Q10: 0.009977754 | R10: 0.015744991 | S10: 0.016278834 | T10: 0.022723268 | U10: 0.015466362 | V10: 0.029835841 | W10: 0.012113068 | X10: 0.017431777 | Y10: 0.0094282978 | Z10: 0.012979754 | AA10: 0.0088193243 | AB10: 0.0085168605 | AC10: 0.0071766406 | AD10: 0.0080853498 | AE10: 0.0096938901
A11: 408 | B11: 0.015014952 | C11: 0.016768268 | D11: 0.032234473 | E11: 0.015290598 | F11: 0.014018594 | G11: 0.0167393 | H11: 0.0167393 | I11: 0.015364198 | J11: 0.01567109 | K11: 0.023871401 | L11: 0.019953516 | M11: 0.01988018 | N11: 0.013839595 | O11: 0.013310287 | P11: 0.023262854 | Q11: 0.0098154533 | R11: 0.015589885 | S11: 0.016110412 | T11: 0.022515173 | U11: 0.015262022 | V11: 0.029604027 | W11: 0.011967383 | X11: 0.017268686 | Y11: 0.0092712255 | Z11: 0.012823645 | AA11: 0.0086550698 | AB11: 0.0083732976 | AC11: 0.0070549633 | AD11: 0.0079379397 | AE11: 0.0095209611
A12: 409 | B12: 0.014815094 | C12: 0.016589804 | D12: 0.03205767 | E12: 0.015068977 | F12: 0.013823701 | G12: 0.016569427 | H12: 0.016569427 | I12: 0.015170307 | J12: 0.015479516 | K12: 0.023648062 | L12: 0.019713534 | M12: 0.019650903 | N12: 0.01364719 | O12: 0.013141001 | P12: 0.023072879 | Q12: 0.0096557927 | R12: 0.015436306 | S12: 0.015943732 | T12: 0.022308983 | U12: 0.015060381 | V12: 0.029374014 | W12: 0.01182345 | X12: 0.017107121 | Y12: 0.00911677 | Z12: 0.012669414 | AA12: 0.0084938745 | AB12: 0.0082321547 | AC12: 0.0069353491 | AD12: 0.0077932172 | AE12: 0.009351117
A13: 410 | B13: 0.014617896 | C13: 0.016413239 | D13: 0.031881837 | E13: 0.014850568 | F13: 0.013631518 | G13: 0.016401278 | H13: 0.016401278 | I13: 0.014978862 | J13: 0.015290284 | K13: 0.023426811 | L13: 0.019476437 | M13: 0.019424269 | N13: 0.013457461 | O13: 0.012973868 | P13: 0.022884455 | Q13: 0.0094987291 | R13: 0.015284241 | S13: 0.015778776 | T13: 0.022104682 | U13: 0.014861404 | V13: 0.029145788 | W13: 0.011681249 | X13: 0.016947068 | Y13: 0.0089648876 | Z13: 0.012517038 | AA13: 0.0083356813 | AB13: 0.0080933909 | AC13: 0.0068177628 | AD13: 0.0076511331 | AE13: 0.0091843027
A14: 411 | B14: 0.014423323 | C14: 0.016238554 | D14: 0.031706968 | E14: 0.014635325 | F14: 0.013442006 | G14: 0.016234835 | H14: 0.016234835 | I14: 0.014789833 | J14: 0.015103365 | K14: 0.023207631 | L14: 0.019242192 | M14: 0.019200249 | N14: 0.013270369 | O14: 0.012808861 | P14: 0.022697569 | Q14: 0.0093442204 | R14: 0.015133673 | S14: 0.015615527 | T14: 0.021902251 | U14: 0.014665056 | V14: 0.028919335 | W14: 0.011540757 | X14: 0.016788512 | Y14: 0.0088155356 | Z14: 0.012366494 | AA14: 0.0081804344 | AB14: 0.0079569662 | AC14: 0.0067021702 | AD14: 0.0075116396 | AE14: 0.0090204642
... A603: 1000 | B603: 5.3870709e-06 | C603: 2.9750429e-05 | D603: 0.0012423894 | E603: 2.6960653e-06 | F603: 3.5259147e-06 | G603: 3.9929466e-05 | H603: 3.9929466e-05 | I603: 8.3427699e-06 | J603: 1.0783022e-05 | K603: 9.143574e-05 | L603: 1.5455434e-05 | M603: 2.0702999e-05 | N603: 3.4808932e-06 | O603: 6.8120455e-06 | P603: 0.00018131088 | Q603: 5.9625508e-07 | R603: 4.4415014e-05 | S603: 3.4138338e-05 | T603: 9.7080905e-05 | U603: 5.8096642e-06 | V603: 0.00029238332 | W603: 9.2695994e-06 | X603: 6.6145053e-05 | Y603: 4.4444492e-07 | Z603: 9.932836e-06 | AA603: 1.2698333e-07 | AB603: 3.565799e-07 | AC603: 2.8316845e-07 | AD603: 1.475791e-07 | AE603: 2.2430492e-07

Sheet Simulated_Rrs (SPM=0)
A1: =0.54*0.0922 -> 0.049788
A2: Wavelength | B2: WMS_04 | C2: WMS_05 | D2: WMS_06 | E2: WMS_07 | F2: WMS_09 | G2: WMS_13 | H2: WMS_14 | I2: WMS_15 | J2: WMS_16 | K2: WMS_17 | L2: WMS_18 | M2: WMS_19 | N2: WMS_20 | O2: WMS_22 | P2: WMS_23 | Q2: WMS_24 | R2: WMS_25 | S2: WMS_26 | T2: WMS_27 | U2: WMS_29 | V2: WMS_30 | W2: WMS_31 | X2: WMS_32 | Y2: WMS_33 | Z2: WMS_34 | AA2: WMS_35 | AB2: WMS_36 | AC2: WMS_37 | AD2: WMS_38 | AE2: WMS_39
A3: 400 | B3: =$A$1*0.0922*(('bb(w)'!B3)/(('a(w)'!B3+'a(CDOM)'!B3+('bb(w)'!B3)))) -> 0.00063895855 | C3: =$A$1*0.0922*(('bb(w)'!C3)/(('a(w)'!C3+'a(CDOM)'!C3+('bb(w)'!C3)))) -> 0.00060435243 | D3: =$A$1*0.0922*(('bb(w)'!D3)/(('a(w)'!D3+'a(CDOM)'!D3+('bb(w)'!D3)))) -> 0.00039301574 | E3: =$A$1*0.0922*(('bb(w)'!E3)/(('a(w)'!E3+'a(CDOM)'!E3+('bb(w)'!E3)))) -> 0.00062804999 | F3: =$A$1*0.0922*(('bb(w)'!F3)/(('a(w)'!F3+'a(CDOM)'!F3+('bb(w)'!F3)))) -> 0.00066428739 | G3: =$A$1*0.0922*(('bb(w)'!G3)/(('a(w)'!G3+'a(CDOM)'!G3+('bb(w)'!G3)))) -> 0.00060656004 | H3: =$A$1*0.0922*(('bb(w)'!H3)/(('a(w)'!H3+'a(CDOM)'!H3+('bb(w)'!H3)))) -> 0.00060656004 | I3: =$A$1*0.0922*(('bb(w)'!I3)/(('a(w)'!I3+'a(CDOM)'!I3+('bb(w)'!I3)))) -> 0.00063212288 | ... AE3: =$A$1*0.0922*(('bb(w)'!AE3)/(('a(w)'!AE3+'a(CDOM)'!AE3+('bb(w)'!AE3)))) -> 0.00080969482
A4: 401 | B4: =$A$1*0.0922*(('bb(w)'!B4)/(('a(w)'!B4+'a(CDOM)'!B4+('bb(w)'!B4)))) -> 0.00064471584 | C4: =$A$1*0.0922*(('bb(w)'!C4)/(('a(w)'!C4+'a(CDOM)'!C4+('bb(w)'!C4)))) -> 0.00060853516 | D4: =$A$1*0.0922*(('bb(w)'!D4)/(('a(w)'!D4+'a(CDOM)'!D4+('bb(w)'!D4)))) -> 0.00039320447 | E4: =$A$1*0.0922*(('bb(w)'!E4)/(('a(w)'!E4+'a(CDOM)'!E4+('bb(w)'!E4)))) -> 0.00063411737 | F4: =$A$1*0.0922*(('bb(w)'!F4)/(('a(w)'!F4+'a(CDOM)'!F4+('bb(w)'!F4)))) -> 0.00067068399 | G4: =$A$1*0.0922*(('bb(w)'!G4)/(('a(w)'!G4+'a(CDOM)'!G4+('bb(w)'!G4)))) -> 0.00061057803 | H4: =$A$1*0.0922*(('bb(w)'!H4)/(('a(w)'!H4+'a(CDOM)'!H4+('bb(w)'!H4)))) -> 0.00061057803 | I4: =$A$1*0.0922*(('bb(w)'!I4)/(('a(w)'!I4+'a(CDOM)'!I4+('bb(w)'!I4)))) -> 0.00063749684 | ... AE4: =$A$1*0.0922*(('bb(w)'!AE4)/(('a(w)'!AE4+'a(CDOM)'!AE4+('bb(w)'!AE4)))) -> 0.00082031998
A5: 402 | B5: =$A$1*0.0922*(('bb(w)'!B5)/(('a(w)'!B5+'a(CDOM)'!B5+('bb(w)'!B5)))) -> 0.00065071217 | C5: =$A$1*0.0922*(('bb(w)'!C5)/(('a(w)'!C5+'a(CDOM)'!C5+('bb(w)'!C5)))) -> 0.00061289888 | D5: =$A$1*0.0922*(('bb(w)'!D5)/(('a(w)'!D5+'a(CDOM)'!D5+('bb(w)'!D5)))) -> 0.00039343936 | E5: =$A$1*0.0922*(('bb(w)'!E5)/(('a(w)'!E5+'a(CDOM)'!E5+('bb(w)'!E5)))) -> 0.00064043024 | F5: =$A$1*0.0922*(('bb(w)'!F5)/(('a(w)'!F5+'a(CDOM)'!F5+('bb(w)'!F5)))) -> 0.00067734852 | G5: =$A$1*0.0922*(('bb(w)'!G5)/(('a(w)'!G5+'a(CDOM)'!G5+('bb(w)'!G5)))) -> 0.0006147729 | H5: =$A$1*0.0922*(('bb(w)'!H5)/(('a(w)'!H5+'a(CDOM)'!H5+('bb(w)'!H5)))) -> 0.0006147729 | I5: =$A$1*0.0922*(('bb(w)'!I5)/(('a(w)'!I5+'a(CDOM)'!I5+('bb(w)'!I5)))) -> 0.00064309564 | ... AE5: =$A$1*0.0922*(('bb(w)'!AE5)/(('a(w)'!AE5+'a(CDOM)'!AE5+('bb(w)'!AE5)))) -> 0.00083142271
A6: 403 | B6: =$A$1*0.0922*(('bb(w)'!B6)/(('a(w)'!B6+'a(CDOM)'!B6+('bb(w)'!B6)))) -> 0.00065696159 | C6: =$A$1*0.0922*(('bb(w)'!C6)/(('a(w)'!C6+'a(CDOM)'!C6+('bb(w)'!C6)))) -> 0.00061745354 | D6: =$A$1*0.0922*(('bb(w)'!D6)/(('a(w)'!D6+'a(CDOM)'!D6+('bb(w)'!D6)))) -> 0.00039372253 | E6: =$A$1*0.0922*(('bb(w)'!E6)/(('a(w)'!E6+'a(CDOM)'!E6+('bb(w)'!E6)))) -> 0.00064700331 | F6: =$A$1*0.0922*(('bb(w)'!F6)/(('a(w)'!F6+'a(CDOM)'!F6+('bb(w)'!F6)))) -> 0.00068429714 | G6: =$A$1*0.0922*(('bb(w)'!G6)/(('a(w)'!G6+'a(CDOM)'!G6+('bb(w)'!G6)))) -> 0.00061915427 | H6: =$A$1*0.0922*(('bb(w)'!H6)/(('a(w)'!H6+'a(CDOM)'!H6+('bb(w)'!H6)))) -> 0.00061915427 | I6: =$A$1*0.0922*(('bb(w)'!I6)/(('a(w)'!I6+'a(CDOM)'!I6+('bb(w)'!I6)))) -> 0.00064893228 | ... AE6: =$A$1*0.0922*(('bb(w)'!AE6)/(('a(w)'!AE6+'a(CDOM)'!AE6+('bb(w)'!AE6)))) -> 0.00084303574
A7: 404 | B7: =$A$1*0.0922*(('bb(w)'!B7)/(('a(w)'!B7+'a(CDOM)'!B7+('bb(w)'!B7)))) -> 0.00066347526 | C7: =$A$1*0.0922*(('bb(w)'!C7)/(('a(w)'!C7+'a(CDOM)'!C7+('bb(w)'!C7)))) -> 0.00062220598 | D7: =$A$1*0.0922*(('bb(w)'!D7)/(('a(w)'!D7+'a(CDOM)'!D7+('bb(w)'!D7)))) -> 0.00039405368 | E7: =$A$1*0.0922*(('bb(w)'!E7)/(('a(w)'!E7+'a(CDOM)'!E7+('bb(w)'!E7)))) -> 0.00065384843 | F7: =$A$1*0.0922*(('bb(w)'!F7)/(('a(w)'!F7+'a(CDOM)'!F7+('bb(w)'!F7)))) -> 0.0006915431 | G7: =$A$1*0.0922*(('bb(w)'!G7)/(('a(w)'!G7+'a(CDOM)'!G7+('bb(w)'!G7)))) -> 0.00062372862 | H7: =$A$1*0.0922*(('bb(w)'!H7)/(('a(w)'!H7+'a(CDOM)'!H7+('bb(w)'!H7)))) -> 0.00062372862 | I7: =$A$1*0.0922*(('bb(w)'!I7)/(('a(w)'!I7+'a(CDOM)'!I7+('bb(w)'!I7)))) -> 0.00065501681 | ... AE7: =$A$1*0.0922*(('bb(w)'!AE7)/(('a(w)'!AE7+'a(CDOM)'!AE7+('bb(w)'!AE7)))) -> 0.00085518977
A8: 405 | B8: =$A$1*0.0922*(('bb(w)'!B8)/(('a(w)'!B8+'a(CDOM)'!B8+('bb(w)'!B8)))) -> 0.00067026668 | C8: =$A$1*0.0922*(('bb(w)'!C8)/(('a(w)'!C8+'a(CDOM)'!C8+('bb(w)'!C8)))) -> 0.00062716499 | D8: =$A$1*0.0922*(('bb(w)'!D8)/(('a(w)'!D8+'a(CDOM)'!D8+('bb(w)'!D8)))) -> 0.0003944335 | E8: =$A$1*0.0922*(('bb(w)'!E8)/(('a(w)'!E8+'a(CDOM)'!E8+('bb(w)'!E8)))) -> 0.00066097991 | F8: =$A$1*0.0922*(('bb(w)'!F8)/(('a(w)'!F8+'a(CDOM)'!F8+('bb(w)'!F8)))) -> 0.00069910225 | G8: =$A$1*0.0922*(('bb(w)'!G8)/(('a(w)'!G8+'a(CDOM)'!G8+('bb(w)'!G8)))) -> 0.00062850437 | H8: =$A$1*0.0922*(('bb(w)'!H8)/(('a(w)'!H8+'a(CDOM)'!H8+('bb(w)'!H8)))) -> 0.00062850437 | I8: =$A$1*0.0922*(('bb(w)'!I8)/(('a(w)'!I8+'a(CDOM)'!I8+('bb(w)'!I8)))) -> 0.00066136153 | ... AE8: =$A$1*0.0922*(('bb(w)'!AE8)/(('a(w)'!AE8+'a(CDOM)'!AE8+('bb(w)'!AE8)))) -> 0.00086792019
A9: 406 | B9: =$A$1*0.0922*(('bb(w)'!B9)/(('a(w)'!B9+'a(CDOM)'!B9+('bb(w)'!B9)))) -> 0.00067308869 | C9: =$A$1*0.0922*(('bb(w)'!C9)/(('a(w)'!C9+'a(CDOM)'!C9+('bb(w)'!C9)))) -> 0.0006286244 | D9: =$A$1*0.0922*(('bb(w)'!D9)/(('a(w)'!D9+'a(CDOM)'!D9+('bb(w)'!D9)))) -> 0.00039341111 | E9: =$A$1*0.0922*(('bb(w)'!E9)/(('a(w)'!E9+'a(CDOM)'!E9+('bb(w)'!E9)))) -> 0.0006642628 | F9: =$A$1*0.0922*(('bb(w)'!F9)/(('a(w)'!F9+'a(CDOM)'!F9+('bb(w)'!F9)))) -> 0.00070235004 | G9: =$A$1*0.0922*(('bb(w)'!G9)/(('a(w)'!G9+'a(CDOM)'!G9+('bb(w)'!G9)))) -> 0.00062976144 | H9: =$A$1*0.0922*(('bb(w)'!H9)/(('a(w)'!H9+'a(CDOM)'!H9+('bb(w)'!H9)))) -> 0.00062976144 | I9: =$A$1*0.0922*(('bb(w)'!I9)/(('a(w)'!I9+'a(CDOM)'!I9+('bb(w)'!I9)))) -> 0.0006638347 | ... AE9: =$A$1*0.0922*(('bb(w)'!AE9)/(('a(w)'!AE9+'a(CDOM)'!AE9+('bb(w)'!AE9)))) -> 0.00087406462
A10: 407 | B10: =$A$1*0.0922*(('bb(w)'!B10)/(('a(w)'!B10+'a(CDOM)'!B10+('bb(w)'!B10)))) -> 0.00067599797 | C10: =$A$1*0.0922*(('bb(w)'!C10)/(('a(w)'!C10+'a(CDOM)'!C10+('bb(w)'!C10)))) -> 0.00063014985 | D10: =$A$1*0.0922*(('bb(w)'!D10)/(('a(w)'!D10+'a(CDOM)'!D10+('bb(w)'!D10)))) -> 0.00039241293 | E10: =$A$1*0.0922*(('bb(w)'!E10)/(('a(w)'!E10+'a(CDOM)'!E10+('bb(w)'!E10)))) -> 0.00066763695 | F10: =$A$1*0.0922*(('bb(w)'!F10)/(('a(w)'!F10+'a(CDOM)'!F10+('bb(w)'!F10)))) -> 0.00070569503 | G10: =$A$1*0.0922*(('bb(w)'!G10)/(('a(w)'!G10+'a(CDOM)'!G10+('bb(w)'!G10)))) -> 0.00063108287 | H10: =$A$1*0.0922*(('bb(w)'!H10)/(('a(w)'!H10+'a(CDOM)'!H10+('bb(w)'!H10)))) -> 0.00063108287 | I10: =$A$1*0.0922*(('bb(w)'!I10)/(('a(w)'!I10+'a(CDOM)'!I10+('bb(w)'!I10)))) -> 0.00066638973 | ... AE10: =$A$1*0.0922*(('bb(w)'!AE10)/(('a(w)'!AE10+'a(CDOM)'!AE10+('bb(w)'!AE10)))) -> 0.0008803771
A11: 408 | B11: =$A$1*0.0922*(('bb(w)'!B11)/(('a(w)'!B11+'a(CDOM)'!B11+('bb(w)'!B11)))) -> 0.00067899837 | C11: =$A$1*0.0922*(('bb(w)'!C11)/(('a(w)'!C11+'a(CDOM)'!C11+('bb(w)'!C11)))) -> 0.00063174402 | D11: =$A$1*0.0922*(('bb(w)'!D11)/(('a(w)'!D11+'a(CDOM)'!D11+('bb(w)'!D11)))) -> 0.00039143971 | E11: =$A$1*0.0922*(('bb(w)'!E11)/(('a(w)'!E11+'a(CDOM)'!E11+('bb(w)'!E11)))) -> 0.00067110644 | F11: =$A$1*0.0922*(('bb(w)'!F11)/(('a(w)'!F11+'a(CDOM)'!F11+('bb(w)'!F11)))) -> 0.00070914154 | G11: =$A$1*0.0922*(('bb(w)'!G11)/(('a(w)'!G11+'a(CDOM)'!G11+('bb(w)'!G11)))) -> 0.00063247124 | H11: =$A$1*0.0922*(('bb(w)'!H11)/(('a(w)'!H11+'a(CDOM)'!H11+('bb(w)'!H11)))) -> 0.00063247124 | I11: =$A$1*0.0922*(('bb(w)'!I11)/(('a(w)'!I11+'a(CDOM)'!I11+('bb(w)'!I11)))) -> 0.00066903015 | ... AE11: =$A$1*0.0922*(('bb(w)'!AE11)/(('a(w)'!AE11+'a(CDOM)'!AE11+('bb(w)'!AE11)))) -> 0.00088686574
A12: 409 | B12: =$A$1*0.0922*(('bb(w)'!B12)/(('a(w)'!B12+'a(CDOM)'!B12+('bb(w)'!B12)))) -> 0.00068208965 | C12: =$A$1*0.0922*(('bb(w)'!C12)/(('a(w)'!C12+'a(CDOM)'!C12+('bb(w)'!C12)))) -> 0.00063340576 | D12: =$A$1*0.0922*(('bb(w)'!D12)/(('a(w)'!D12+'a(CDOM)'!D12+('bb(w)'!D12)))) -> 0.00039048962 | E12: =$A$1*0.0922*(('bb(w)'!E12)/(('a(w)'!E12+'a(CDOM)'!E12+('bb(w)'!E12)))) -> 0.00067467139 | F12: =$A$1*0.0922*(('bb(w)'!F12)/(('a(w)'!F12+'a(CDOM)'!F12+('bb(w)'!F12)))) -> 0.0007126897 | G12: =$A$1*0.0922*(('bb(w)'!G12)/(('a(w)'!G12+'a(CDOM)'!G12+('bb(w)'!G12)))) -> 0.00063392526 | H12: =$A$1*0.0922*(('bb(w)'!H12)/(('a(w)'!H12+'a(CDOM)'!H12+('bb(w)'!H12)))) -> 0.00063392526 | I12: =$A$1*0.0922*(('bb(w)'!I12)/(('a(w)'!I12+'a(CDOM)'!I12+('bb(w)'!I12)))) -> 0.00067175548 | ... AE12: =$A$1*0.0922*(('bb(w)'!AE12)/(('a(w)'!AE12+'a(CDOM)'!AE12+('bb(w)'!AE12)))) -> 0.00089353384
A13: 410 | B13: =$A$1*0.0922*(('bb(w)'!B13)/(('a(w)'!B13+'a(CDOM)'!B13+('bb(w)'!B13)))) -> 0.00068527666 | C13: =$A$1*0.0922*(('bb(w)'!C13)/(('a(w)'!C13+'a(CDOM)'!C13+('bb(w)'!C13)))) -> 0.00063513861 | D13: =$A$1*0.0922*(('bb(w)'!D13)/(('a(w)'!D13+'a(CDOM)'!D13+('bb(w)'!D13)))) -> 0.00038956391 | E13: =$A$1*0.0922*(('bb(w)'!E13)/(('a(w)'!E13+'a(CDOM)'!E13+('bb(w)'!E13)))) -> 0.00067833695 | F13: =$A$1*0.0922*(('bb(w)'!F13)/(('a(w)'!F13+'a(CDOM)'!F13+('bb(w)'!F13)))) -> 0.00071634492 | G13: =$A$1*0.0922*(('bb(w)'!G13)/(('a(w)'!G13+'a(CDOM)'!G13+('bb(w)'!G13)))) -> 0.00063544836 | H13: =$A$1*0.0922*(('bb(w)'!H13)/(('a(w)'!H13+'a(CDOM)'!H13+('bb(w)'!H13)))) -> 0.00063544836 | I13: =$A$1*0.0922*(('bb(w)'!I13)/(('a(w)'!I13+'a(CDOM)'!I13+('bb(w)'!I13)))) -> 0.00067457023 | ... AE13: =$A$1*0.0922*(('bb(w)'!AE13)/(('a(w)'!AE13+'a(CDOM)'!AE13+('bb(w)'!AE13)))) -> 0.00090039118
A14: 411 | B14: =$A$1*0.0922*(('bb(w)'!B14)/(('a(w)'!B14+'a(CDOM)'!B14+('bb(w)'!B14)))) -> 0.00068684469 | C14: =$A$1*0.0922*(('bb(w)'!C14)/(('a(w)'!C14+'a(CDOM)'!C14+('bb(w)'!C14)))) -> 0.00063547421 | D14: =$A$1*0.0922*(('bb(w)'!D14)/(('a(w)'!D14+'a(CDOM)'!D14+('bb(w)'!D14)))) -> 0.00038811457 | E14: =$A$1*0.0922*(('bb(w)'!E14)/(('a(w)'!E14+'a(CDOM)'!E14+('bb(w)'!E14)))) -> 0.00068042074 | F14: =$A$1*0.0922*(('bb(w)'!F14)/(('a(w)'!F14+'a(CDOM)'!F14+('bb(w)'!F14)))) -> 0.00071823225 | G14: =$A$1*0.0922*(('bb(w)'!G14)/(('a(w)'!G14+'a(CDOM)'!G14+('bb(w)'!G14)))) -> 0.00063557159 | H14: =$A$1*0.0922*(('bb(w)'!H14)/(('a(w)'!H14+'a(CDOM)'!H14+('bb(w)'!H14)))) -> 0.00063557159 | I14: =$A$1*0.0922*(('bb(w)'!I14)/(('a(w)'!I14+'a(CDOM)'!I14+('bb(w)'!I14)))) -> 0.00067581413 | ... AE14: =$A$1*0.0922*(('bb(w)'!AE14)/(('a(w)'!AE14+'a(CDOM)'!AE14+('bb(w)'!AE14)))) -> 0.00090446475
... A603: 1000 | B603: =$A$1*0.0922*(('bb(w)'!B603)/(('a(w)'!B603+'a(CDOM)'!B603+('bb(w)'!B603)))) -> 8.634965e-09 | C603: =$A$1*0.0922*(('bb(w)'!C603)/(('a(w)'!C603+'a(CDOM)'!C603+('bb(w)'!C603)))) -> 8.6349598e-09 | D603: =$A$1*0.0922*(('bb(w)'!D603)/(('a(w)'!D603+'a(CDOM)'!D603+('bb(w)'!D603)))) -> 8.6347027e-09 | E603: =$A$1*0.0922*(('bb(w)'!E603)/(('a(w)'!E603+'a(CDOM)'!E603+('bb(w)'!E603)))) -> 8.6349656e-09 | F603: =$A$1*0.0922*(('bb(w)'!F603)/(('a(w)'!F603+'a(CDOM)'!F603+('bb(w)'!F603)))) -> 8.6349654e-09 | G603: =$A$1*0.0922*(('bb(w)'!G603)/(('a(w)'!G603+'a(CDOM)'!G603+('bb(w)'!G603)))) -> 8.6349577e-09 | H603: =$A$1*0.0922*(('bb(w)'!H603)/(('a(w)'!H603+'a(CDOM)'!H603+('bb(w)'!H603)))) -> 8.6349577e-09 | I603: =$A$1*0.0922*(('bb(w)'!I603)/(('a(w)'!I603+'a(CDOM)'!I603+('bb(w)'!I603)))) -> 8.6349644e-09 | ... AE603: =$A$1*0.0922*(('bb(w)'!AE603)/(('a(w)'!AE603+'a(CDOM)'!AE603+('bb(w)'!AE603)))) -> 8.6349661e-09

Sheet Simulated_Rrs (SPM)
A1: =0.54*0.0922 -> 0.049788
A2: Wavelength | B2: WMS_04 | C2: WMS_05 | D2: WMS_06 | E2: WMS_07 | F2: WMS_09 | G2: WMS_13 | H2: WMS_14 | I2: WMS_15 | J2: WMS_16 | K2: WMS_17 | L2: WMS_18 | M2: WMS_19 | N2: WMS_20 | O2: WMS_22 | P2: WMS_23 | Q2: WMS_24 | R2: WMS_25 | S2: WMS_26 | T2: WMS_27 | U2: WMS_29 | V2: WMS_30 | W2: WMS_31 | X2: WMS_32 | Y2: WMS_33 | Z2: WMS_34 | AA2: WMS_35 | AB2: WMS_36 | AC2: WMS_37 | AD2: WMS_38 | AE2: WMS_39
A3: 400 | B3: ='Radiometer Rrs'!B3-'Simulated_Rrs (SPM=0)'!B3 -> 0.0045913386 | C3: ='Radiometer Rrs'!C3-'Simulated_Rrs (SPM=0)'!C3 -> 0.0043370663 | D3: ='Radiometer Rrs'!D3-'Simulated_Rrs (SPM=0)'!D3 -> 0.0034913133 | E3: ='Radiometer Rrs'!E3-'Simulated_Rrs (SPM=0)'!E3 -> 0.0034998063 | F3: ='Radiometer Rrs'!F3-'Simulated_Rrs (SPM=0)'!F3 -> 0.0033078319 | G3: ='Radiometer Rrs'!G3-'Simulated_Rrs (SPM=0)'!G3 -> 0.0020897354 | H3: ='Radiometer Rrs'!H3-'Simulated_Rrs (SPM=0)'!H3 -> 0.0019346142 | I3: ='Radiometer Rrs'!I3-'Simulated_Rrs (SPM=0)'!I3 -> 0.0016839485 | ... AE3: ='Radiometer Rrs'!AE3-'Simulated_Rrs (SPM=0)'!AE3 -> 0.0082211722
A4: 401 | B4: ='Radiometer Rrs'!B4-'Simulated_Rrs (SPM=0)'!B4 -> 0.0045975831 | C4: ='Radiometer Rrs'!C4-'Simulated_Rrs (SPM=0)'!C4 -> 0.0043294953 | D4: ='Radiometer Rrs'!D4-'Simulated_Rrs (SPM=0)'!D4 -> 0.003491585 | E4: ='Radiometer Rrs'!E4-'Simulated_Rrs (SPM=0)'!E4 -> 0.003488575 | F4: ='Radiometer Rrs'!F4-'Simulated_Rrs (SPM=0)'!F4 -> 0.0032894041 | G4: ='Radiometer Rrs'!G4-'Simulated_Rrs (SPM=0)'!G4 -> 0.0021751826 | H4: ='Radiometer Rrs'!H4-'Simulated_Rrs (SPM=0)'!H4 -> 0.00191769 | I4: ='Radiometer Rrs'!I4-'Simulated_Rrs (SPM=0)'!I4 -> 0.0016769516 | ... AE4: ='Radiometer Rrs'!AE4-'Simulated_Rrs (SPM=0)'!AE4 -> 0.0082093219
A5: 402 | B5: ='Radiometer Rrs'!B5-'Simulated_Rrs (SPM=0)'!B5 -> 0.0046158571 | C5: ='Radiometer Rrs'!C5-'Simulated_Rrs (SPM=0)'!C5 -> 0.0043288905 | D5: ='Radiometer Rrs'!D5-'Simulated_Rrs (SPM=0)'!D5 -> 0.0034968526 | E5: ='Radiometer Rrs'!E5-'Simulated_Rrs (SPM=0)'!E5 -> 0.0034804383 | F5: ='Radiometer Rrs'!F5-'Simulated_Rrs (SPM=0)'!F5 -> 0.0032781595 | G5: ='Radiometer Rrs'!G5-'Simulated_Rrs (SPM=0)'!G5 -> 0.0022600206 | H5: ='Radiometer Rrs'!H5-'Simulated_Rrs (SPM=0)'!H5 -> 0.0019000556 | I5: ='Radiometer Rrs'!I5-'Simulated_Rrs (SPM=0)'!I5 -> 0.0016731256 | ... AE5: ='Radiometer Rrs'!AE5-'Simulated_Rrs (SPM=0)'!AE5 -> 0.0081901022
A6: 403 | B6: ='Radiometer Rrs'!B6-'Simulated_Rrs (SPM=0)'!B6 -> 0.0046311906 | C6: ='Radiometer Rrs'!C6-'Simulated_Rrs (SPM=0)'!C6 -> 0.0043524493 | D6: ='Radiometer Rrs'!D6-'Simulated_Rrs (SPM=0)'!D6 -> 0.003525226 | E6: ='Radiometer Rrs'!E6-'Simulated_Rrs (SPM=0)'!E6 -> 0.0035022349 | F6: ='Radiometer Rrs'!F6-'Simulated_Rrs (SPM=0)'!F6 -> 0.0032977731 | G6: ='Radiometer Rrs'!G6-'Simulated_Rrs (SPM=0)'!G6 -> 0.0022962667 | H6: ='Radiometer Rrs'!H6-'Simulated_Rrs (SPM=0)'!H6 -> 0.0018980929 | I6: ='Radiometer Rrs'!I6-'Simulated_Rrs (SPM=0)'!I6 -> 0.0016787411 | ... AE6: ='Radiometer Rrs'!AE6-'Simulated_Rrs (SPM=0)'!AE6 -> 0.0081960472
A7: 404 | B7: ='Radiometer Rrs'!B7-'Simulated_Rrs (SPM=0)'!B7 -> 0.0046532723 | C7: ='Radiometer Rrs'!C7-'Simulated_Rrs (SPM=0)'!C7 -> 0.0043750095 | D7: ='Radiometer Rrs'!D7-'Simulated_Rrs (SPM=0)'!D7 -> 0.003552972 | E7: ='Radiometer Rrs'!E7-'Simulated_Rrs (SPM=0)'!E7 -> 0.003526083 | F7: ='Radiometer Rrs'!F7-'Simulated_Rrs (SPM=0)'!F7 -> 0.0033183184 | G7: ='Radiometer Rrs'!G7-'Simulated_Rrs (SPM=0)'!G7 -> 0.0023271685 | H7: ='Radiometer Rrs'!H7-'Simulated_Rrs (SPM=0)'!H7 -> 0.0018963774 | I7: ='Radiometer Rrs'!I7-'Simulated_Rrs (SPM=0)'!I7 -> 0.0016824579 | ... AE7: ='Radiometer Rrs'!AE7-'Simulated_Rrs (SPM=0)'!AE7 -> 0.0081902407
A8: 405 | B8: ='Radiometer Rrs'!B8-'Simulated_Rrs (SPM=0)'!B8 -> 0.0046875429 | C8: ='Radiometer Rrs'!C8-'Simulated_Rrs (SPM=0)'!C8 -> 0.0043959392 | D8: ='Radiometer Rrs'!D8-'Simulated_Rrs (SPM=0)'!D8 -> 0.0035796394 | E8: ='Radiometer Rrs'!E8-'Simulated_Rrs (SPM=0)'!E8 -> 0.0035537758 | F8: ='Radiometer Rrs'!F8-'Simulated_Rrs (SPM=0)'!F8 -> 0.0033407353 | G8: ='Radiometer Rrs'!G8-'Simulated_Rrs (SPM=0)'!G8 -> 0.0023487115 | H8: ='Radiometer Rrs'!H8-'Simulated_Rrs (SPM=0)'!H8 -> 0.0018952432 | I8: ='Radiometer Rrs'!I8-'Simulated_Rrs (SPM=0)'!I8 -> 0.0016829796 | ... AE8: ='Radiometer Rrs'!AE8-'Simulated_Rrs (SPM=0)'!AE8 -> 0.0081639282
A9: 406 | B9: ='Radiometer Rrs'!B9-'Simulated_Rrs (SPM=0)'!B9 -> 0.0047198276 | C9: ='Radiometer Rrs'!C9-'Simulated_Rrs (SPM=0)'!C9 -> 0.004428949 | D9: ='Radiometer Rrs'!D9-'Simulated_Rrs (SPM=0)'!D9 -> 0.0036185929 | E9: ='Radiometer Rrs'!E9-'Simulated_Rrs (SPM=0)'!E9 -> 0.0035834547 | F9: ='Radiometer Rrs'!F9-'Simulated_Rrs (SPM=0)'!F9 -> 0.003371898 | G9: ='Radiometer Rrs'!G9-'Simulated_Rrs (SPM=0)'!G9 -> 0.0023570973 | H9: ='Radiometer Rrs'!H9-'Simulated_Rrs (SPM=0)'!H9 -> 0.0019022371 | I9: ='Radiometer Rrs'!I9-'Simulated_Rrs (SPM=0)'!I9 -> 0.0016867853 | ... AE9: ='Radiometer Rrs'!AE9-'Simulated_Rrs (SPM=0)'!AE9 -> 0.0081443569
A10: 407 | B10: ='Radiometer Rrs'!B10-'Simulated_Rrs (SPM=0)'!B10 -> 0.0047489571 | C10: ='Radiometer Rrs'!C10-'Simulated_Rrs (SPM=0)'!C10 -> 0.0044663128 | D10: ='Radiometer Rrs'!D10-'Simulated_Rrs (SPM=0)'!D10 -> 0.0036631289 | E10: ='Radiometer Rrs'!E10-'Simulated_Rrs (SPM=0)'!E10 -> 0.0036120828 | F10: ='Radiometer Rrs'!F10-'Simulated_Rrs (SPM=0)'!F10 -> 0.0034052479 | G10: ='Radiometer Rrs'!G10-'Simulated_Rrs (SPM=0)'!G10 -> 0.0023568283 | H10: ='Radiometer Rrs'!H10-'Simulated_Rrs (SPM=0)'!H10 -> 0.0019115411 | I10: ='Radiometer Rrs'!I10-'Simulated_Rrs (SPM=0)'!I10 -> 0.0016902065 | ... AE10: ='Radiometer Rrs'!AE10-'Simulated_Rrs (SPM=0)'!AE10 -> 0.0081246976
A11: 408 | B11: ='Radiometer Rrs'!B11-'Simulated_Rrs (SPM=0)'!B11 -> 0.004752381 | C11: ='Radiometer Rrs'!C11-'Simulated_Rrs (SPM=0)'!C11 -> 0.0044908341 | D11: ='Radiometer Rrs'!D11-'Simulated_Rrs (SPM=0)'!D11 -> 0.0036737803 | E11: ='Radiometer Rrs'!E11-'Simulated_Rrs (SPM=0)'!E11 -> 0.0036390242 | F11: ='Radiometer Rrs'!F11-'Simulated_Rrs (SPM=0)'!F11 -> 0.0034102826 | G11: ='Radiometer Rrs'!G11-'Simulated_Rrs (SPM=0)'!G11 -> 0.0023244579 | H11: ='Radiometer Rrs'!H11-'Simulated_Rrs (SPM=0)'!H11 -> 0.0019159172 | I11: ='Radiometer Rrs'!I11-'Simulated_Rrs (SPM=0)'!I11 -> 0.0016976227 | ... AE11: ='Radiometer Rrs'!AE11-'Simulated_Rrs (SPM=0)'!AE11 -> 0.0081338343
A12: 409 | B12: ='Radiometer Rrs'!B12-'Simulated_Rrs (SPM=0)'!B12 -> 0.0047674763 | C12: ='Radiometer Rrs'!C12-'Simulated_Rrs (SPM=0)'!C12 -> 0.0045150695 | D12: ='Radiometer Rrs'!D12-'Simulated_Rrs (SPM=0)'!D12 -> 0.0036902366 | E12: ='Radiometer Rrs'!E12-'Simulated_Rrs (SPM=0)'!E12 -> 0.0036689484 | F12: ='Radiometer Rrs'!F12-'Simulated_Rrs (SPM=0)'!F12 -> 0.0034253539 | G12: ='Radiometer Rrs'!G12-'Simulated_Rrs (SPM=0)'!G12 -> 0.0023017574 | H12: ='Radiometer Rrs'!H12-'Simulated_Rrs (SPM=0)'!H12 -> 0.0019185721 | I12: ='Radiometer Rrs'!I12-'Simulated_Rrs (SPM=0)'!I12 -> 0.0017030372 | ... AE12: ='Radiometer Rrs'!AE12-'Simulated_Rrs (SPM=0)'!AE12 -> 0.0081357898
A13: 410 | B13: ='Radiometer Rrs'!B13-'Simulated_Rrs (SPM=0)'!B13 -> 0.0048189908 | C13: ='Radiometer Rrs'!C13-'Simulated_Rrs (SPM=0)'!C13 -> 0.0045401274 | D13: ='Radiometer Rrs'!D13-'Simulated_Rrs (SPM=0)'!D13 -> 0.0037272712 | E13: ='Radiometer Rrs'!E13-'Simulated_Rrs (SPM=0)'!E13 -> 0.0037077221 | F13: ='Radiometer Rrs'!F13-'Simulated_Rrs (SPM=0)'!F13 -> 0.0034725188 | G13: ='Radiometer Rrs'!G13-'Simulated_Rrs (SPM=0)'!G13 -> 0.0023104954 | H13: ='Radiometer Rrs'!H13-'Simulated_Rrs (SPM=0)'!H13 -> 0.001917022 | I13: ='Radiometer Rrs'!I13-'Simulated_Rrs (SPM=0)'!I13 -> 0.0017024226 | ... AE13: ='Radiometer Rrs'!AE13-'Simulated_Rrs (SPM=0)'!AE13 -> 0.0081141919
A14: 411 | B14: ='Radiometer Rrs'!B14-'Simulated_Rrs (SPM=0)'!B14 -> 0.0048554796 | C14: ='Radiometer Rrs'!C14-'Simulated_Rrs (SPM=0)'!C14 -> 0.0045727531 | D14: ='Radiometer Rrs'!D14-'Simulated_Rrs (SPM=0)'!D14 -> 0.0037585366 | E14: ='Radiometer Rrs'!E14-'Simulated_Rrs (SPM=0)'!E14 -> 0.0037368685 | F14: ='Radiometer Rrs'!F14-'Simulated_Rrs (SPM=0)'!F14 -> 0.0035050405 | G14: ='Radiometer Rrs'!G14-'Simulated_Rrs (SPM=0)'!G14 -> 0.0023094949 | H14: ='Radiometer Rrs'!H14-'Simulated_Rrs (SPM=0)'!H14 -> 0.001920044 | I14: ='Radiometer Rrs'!I14-'Simulated_Rrs (SPM=0)'!I14 -> 0.0017094099 | ... AE14: ='Radiometer Rrs'!AE14-'Simulated_Rrs (SPM=0)'!AE14 -> 0.0081281072
... A603: 1000 | B603: ='Radiometer Rrs'!B603-'Simulated_Rrs (SPM=0)'!B603 -> 0.0018324962 | C603: ='Radiometer Rrs'!C603-'Simulated_Rrs (SPM=0)'!C603 -> 0.0019056941 | D603: ='Radiometer Rrs'!D603-'Simulated_Rrs (SPM=0)'!D603 -> 0.0017899264 | E603: ='Radiometer Rrs'!E603-'Simulated_Rrs (SPM=0)'!E603 -> 0.0019632821 | F603: ='Radiometer Rrs'!F603-'Simulated_Rrs (SPM=0)'!F603 -> 0.0016161323 | G603: ='Radiometer Rrs'!G603-'Simulated_Rrs (SPM=0)'!G603 -> 0.0020763715 | H603: ='Radiometer Rrs'!H603-'Simulated_Rrs (SPM=0)'!H603 -> 0.001578214 | I603: ='Radiometer Rrs'!I603-'Simulated_Rrs (SPM=0)'!I603 -> 0.0016390767 | ... AE603: ='Radiometer Rrs'!AE603-'Simulated_Rrs (SPM=0)'!AE603 -> 0.0077767015

Sheet Radiometer Rrs
A2: Wavelength | B2: WMS_04 | C2: WMS_05 | D2: WMS_06 | E2: WMS_07 | F2: WMS_09 | G2: WMS_13 | H2: WMS_14 | I2: WMS_15 | J2: WMS_16 | K2: WMS_17 | L2: WMS_18 | M2: WMS_19 | N2: WMS_20 | O2: WMS_22 | P2: WMS_23 | Q2: WMS_24 | R2: WMS_25 | S2: WMS_26 | T2: WMS_27 | U2: WMS_29 | V2: WMS_30 | W2: WMS_31 | X2: WMS_32 | Y2: WMS_33 | Z2: WMS_34 | AA2: WMS_35 | AB2: WMS_36 | AC2: WMS_37 | AD2: WMS_38 | AE2: WMS_39
A3: 400 | B3: 0.0052302972 | C3: 0.0049414187 | D3: 0.003884329 | E3: 0.0041278563 | F3: 0.0039721193 | G3: 0.0026962955 | H3: 0.0025411743 | I3: 0.0023160714 | J3: 0.0037734273 | K3: 0.015588019 | L3: 0.002362873 | M3: 0.0032302317 | N3: 0.0031105908 | O3: 0.0034790207 | P3: 0.001746422 | Q3: 0.0019657654 | R3: 0.001746422 | S3: 0.0037972643 | T3: 0.0012628528 | U3: 0.0082535255 | V3: 0.0041953233 | W3: 0.0035003632 | X3: 0.010179417 | Y3: 0.0092169328 | Z3: 0.014827458 | AA3: 0.009030867 | AB3: 0.0090895865 | AC3: 0.0019613264 | AD3: 0.0069471461 | AE3: 0.009030867
A4: 401 | B4: 0.0052422989 | C4: 0.0049380304 | D4: 0.0038847895 | E4: 0.0041226923 | F4: 0.0039600881 | G4: 0.0027857607 | H4: 0.002528268 | I4: 0.0023144485 | J4: 0.0037539648 | K4: 0.015557096 | L4: 0.0023615938 | M4: 0.0032153955 | N4: 0.0030979549 | O4: 0.003475042 | P4: 0.001742324 | Q4: 0.0019657997 | R4: 0.001742324 | S4: 0.0037436296 | T4: 0.0012805666 | U4: 0.0083772484 | V4: 0.0041787557 | W4: 0.0034853822 | X4: 0.010158286 | Y4: 0.0092365472 | Z4: 0.014759713 | AA4: 0.0090296419 | AB4: 0.0090653779 | AC4: 0.0019564767 | AD4: 0.0069202899 | AE4: 0.0090296419
A5: 402 | B5: 0.0052665693 | C5: 0.0049417893 | D5: 0.003890292 | E5: 0.0041208686 | F5: 0.003955508 | G5: 0.0028747936 | H5: 0.0025148285 | I5: 0.0023162212 | J5: 0.0037387468 | K5: 0.015530077 | L5: 0.0023664429 | M5: 0.0032019111 | N5: 0.0030899442 | O5: 0.0034723098 | P5: 0.0017429338 | Q5: 0.0019700572 | R5: 0.0017429338 | S5: 0.0037038069 | T5: 0.0012909986 | U5: 0.0084821362 | V5: 0.0041697711 | W5: 0.0034728449 | X5: 0.010140877 | Y5: 0.0092630315 | Z5: 0.014700574 | AA5: 0.0090215249 | AB5: 0.0090445613 | AC5: 0.0019540826 | AD5: 0.0068984507 | AE5: 0.0090215249
A6: 403 | B6: 0.0052881521 | C6: 0.0049699029 | D6: 0.0039189485 | E6: 0.0041492382 | F6: 0.0039820702 | G6: 0.0029154209 | H6: 0.0025172471 | I6: 0.0023276734 | J6: 0.003745576 | K6: 0.015500504 | L6: 0.0023779078 | M6: 0.0032013386 | N6: 0.0030945303 | O6: 0.0034692924 | P6: 0.001743635 | Q6: 0.0019723397 | R6: 0.001743635 | S6: 0.0037011725 | T6: 0.0013021913 | U6: 0.0085449997 | V6: 0.0041857413 | W6: 0.0035059951 | X6: 0.010143942 | Y6: 0.0092769921 | Z6: 0.014647459 | AA6: 0.0090390829 | AB6: 0.0090581458 | AC6: 0.0019525537 | AD6: 0.0069091257 | AE6: 0.0090390829
A7: 404 | B7: 0.0053167475 | C7: 0.0049972155 | D7: 0.0039470257 | E7: 0.0041799314 | F7: 0.0040098615 | G7: 0.0029508972 | H7: 0.0025201061 | I7: 0.0023374747 | J7: 0.0037557565 | K7: 0.015494468 | L7: 0.002390163 | M7: 0.0032016227 | N7: 0.0031001075 | O7: 0.0034716342 | P7: 0.0017465384 | Q7: 0.0019743552 | R7: 0.0017465384 | S7: 0.0037117948 | T7: 0.0013106004 | U7: 0.0085783468 | V7: 0.0042099002 | W7: 0.0035301045 | X7: 0.010146996 | Y7: 0.0092907328 | Z7: 0.014623641 | AA7: 0.0090454304 | AB7: 0.0090658676 | AC7: 0.0019569883 | AD7: 0.0069223437 | AE7: 0.0090454304
A8: 405 | B8: 0.0053578096 | C8: 0.0050231042 | D8: 0.0039740729 | E8: 0.0042147557 | F8: 0.0040398375 | G8: 0.0029772159 | H8: 0.0025237476 | I8: 0.0023443411 | J8: 0.0037718947 | K8: 0.015530277 | L8: 0.002403823 | M8: 0.0032034297 | N8: 0.0031074465 | O8: 0.0034835033 | P8: 0.0017533569 | Q8: 0.0019758959 | R8: 0.0017533569 | S8: 0.0037459845 | T8: 0.0013140608 | U8: 0.0085592204 | V8: 0.004248617 | W8: 0.0035381413 | X8: 0.010150032 | Y8: 0.0093040822 | Z8: 0.014651906 | AA8: 0.0090318484 | AB8: 0.0090631666 | AC8: 0.0019720248 | AD8: 0.0069400824 | AE8: 0.0090318484
A9: 406 | B9: 0.0053929163 | C9: 0.0050575734 | D9: 0.004012004 | E9: 0.0042477175 | F9: 0.004074248 | G9: 0.0029868588 | H9: 0.0025319985 | I9: 0.00235062 | J9: 0.0037906128 | K9: 0.015550554 | L9: 0.0024243323 | M9: 0.0032074141 | N9: 0.0031110919 | O9: 0.0034900043 | P9: 0.001765534 | Q9: 0.0019831077 | R9: 0.001765534 | S9: 0.0037744086 | T9: 0.0013127367 | U9: 0.0085254753 | V9: 0.0042877331 | W9: 0.003524664 | X9: 0.010152504 | Y9: 0.0093157013 | Z9: 0.014668123 | AA9: 0.0090184215 | AB9: 0.0090555223 | AC9: 0.0019783136 | AD9: 0.0069648281 | AE9: 0.0090184215
A10: 407 | B10: 0.005424955 | C10: 0.0050964627 | D10: 0.0040555418 | E10: 0.0042797197 | F10: 0.0041109429 | G10: 0.0029879111 | H10: 0.002542624 | I10: 0.0023565962 | J10: 0.00381066 | K10: 0.015562832 | L10: 0.0024483702 | M10: 0.0032125201 | N10: 0.0031128344 | O10: 0.0034937399 | P10: 0.0017804716 | Q10: 0.001993241 | R10: 0.0017804716 | S10: 0.0037998625 | T10: 0.001308948 | U10: 0.0084841992 | V10: 0.0043270549 | W10: 0.0035001037 | X10: 0.010154687 | Y10: 0.009326429 | Z10: 0.014678133 | AA10: 0.0090050747 | AB10: 0.0090453314 | AC10: 0.0019800959 | AD10: 0.0069931835 | AE10: 0.0090050747
A11: 408 | B11: 0.0054313794 | C11: 0.0051225781 | D11: 0.0040652201 | E11: 0.0043101306 | F11: 0.0041194241 | G11: 0.0029569292 | H11: 0.0025483885 | I11: 0.0023666529 | J11: 0.0038257907 | K11: 0.015610799 | L11: 0.0024544941 | M11: 0.0032221459 | N11: 0.0031172513 | O11: 0.0034928537 | P11: 0.0017864206 | Q11: 0.0020052111 | R11: 0.0017864206 | S11: 0.0038358196 | T11: 0.0013139001 | U11: 0.0084632165 | V11: 0.004364659 | W11: 0.0035239763 | X11: 0.010150378 | Y11: 0.0093409802 | Z11: 0.014707111 | AA11: 0.0090207001 | AB11: 0.0090366882 | AC11: 0.0019935729 | AD11: 0.0070271963 | AE11: 0.0090207001
A12: 409 | B12: 0.005449566 | C12: 0.0051484753 | D12: 0.0040807262 | E12: 0.0043436198 | F12: 0.0041380436 | G12: 0.0029356826 | H12: 0.0025524973 | I12: 0.0023747927 | J12: 0.0038380557 | K12: 0.015649822 | L12: 0.0024628624 | M12: 0.0032299687 | N12: 0.003120913 | O12: 0.0034940682 | P12: 0.0017916585 | Q12: 0.0020148884 | R12: 0.0017916585 | S12: 0.003868428 | T12: 0.0013221388 | U12: 0.0084492627 | V12: 0.0043995247 | W12: 0.0035353412 | X12: 0.010158327 | Y12: 0.0093526363 | Z12: 0.014731857 | AA12: 0.0090293236 | AB12: 0.0090334676 | AC12: 0.0020036263 | AD12: 0.0070526753 | AE12: 0.0090293236
A13: 410 | B13: 0.0055042674 | C13: 0.005175266 | D13: 0.0041168351 | E13: 0.0043860591 | F13: 0.0041888638 | G13: 0.0029459437 | H13: 0.0025524704 | I13: 0.0023769928 | J13: 0.0038427478 | K13: 0.015659156 | L13: 0.0024797432 | M13: 0.0032321236 | N13: 0.0031221082 | O13: 0.0035018102 | P13: 0.001795938 | Q13: 0.0020178226 | R13: 0.001795938 | S13: 0.0038902602 | T13: 0.0013386951 | U13: 0.0084529078 | V13: 0.0044268006 | W13: 0.0035053637 | X13: 0.010201931 | Y13: 0.0093555989 | Z13: 0.014742309 | AA13: 0.0090145831 | AB13: 0.0090454973 | AC13: 0.0020025486 | AD13: 0.0070531951 | AE13: 0.0090145831
A14: 411 | B14: 0.0055423243 | C14: 0.0052082273 | D14: 0.0041466512 | E14: 0.0044172892 | F14: 0.0042232727 | G14: 0.0029450665 | H14: 0.0025556156 | I14: 0.002385224 | J14: 0.0038457241 | K14: 0.015687579 | L14: 0.0024949754 | M14: 0.0032337942 | N14: 0.0031219832 | O14: 0.0035086987 | P14: 0.0018031904 | Q14: 0.002021041 | R14: 0.0018031904 | S14: 0.0039051673 | T14: 0.0013578495 | U14: 0.0084551363 | V14: 0.0044524765 | W14: 0.0035086729 | X14: 0.010222979 | Y14: 0.0093610065 | Z14: 0.014756812 | AA14: 0.0090325719 | AB14: 0.0090421297 | AC14: 0.0020058973 | AD14: 0.007058709 | AE14: 0.0090325719
... A603: 1000 | B603: 0.0018325048 | C603: 0.0019057028 | D603: 0.0017899351 | E603: 0.0019632907 | F603: 0.0016161409 | G603: 0.0020763802 | H603: 0.0015782226 | I603: 0.0016390853 | J603: 0.0023139907 | K603: 0.015418593 | L603: 0.0024364167 | M603: 0.0016735155 | N603: 0.0023283213 | O603: 0.0030609749 | P603: 0.0010610144 | Q603: 0.0010254029 | R603: 0.0010610144 | S603: 0.0024899365 | T603: 0.00017963428 | U603: 0.008101805 | V603: 0.0057356634 | W603: 0.0018519933 | X603: 0.006599842 | Y603: 0.0075249266 | Z603: 0.012239258 | AA603: 0.0077767101 | AB603: 0.0065690588 | AC603: 0.0007307049 | AD603: 0.006462548 | AE603: 0.0077767101

Sheet Hypers.sim
A1: Sites | B1: SPM | C1: 400 | D1: 570 | E1: 620 | F1: Rrs 640 | G1: 748 | H1: Rrs 880 | I1: 470 | J1: 471 | K1: 472 | L1: 473 | M1: 474 | N1: 475 | O1: 476 | P1: 477 | Q1: 478 | R1: 479 | S1: 480 | T1: 481 | U1: 482 | V1: 483 | W1: 484 | X1: 485 | Y1: 486 | Z1: 487 | AA1: 488 | AB1: 489 | AC1: 490 | AD1: 491 | AE1: 492 | AF1: 493 | AG1: 494 | AH1: 495 | AI1: 496 | AJ1: 497 | AK1: 498 | AL1: 499 | AM1: 500 | AN1: 550 | AO1: 551 | AP1: 552 | AQ1: 553 | AR1: 554 | AS1: 555 | AT1: 556 | AU1: 557 | AV1: 558 | AW1: 559 | AX1: 560 | AY1: 561 | AZ1: 562 | BA1: 563 | BB1: 564 | BC1: 565 | BD1: 610 | BE1: 611 | BF1: 612 | BG1: 613 | BH1: 614 | BI1: 615 | BJ1: 616 | BK1: 617 | BL1: 618 | BM1: 619 | BN1: 620 | BO1: 621 | BP1: 622 | BQ1: 623 | BR1: 624 | BS1: 625 | BT1: 626 | BU1: 627 | BV1: 628 | BW1: 629 | BX1: 630 | BY1: 631 | BZ1: 632 | CA1: 633 | CB1: 634 | CC1: 635 | CD1: 636 | CE1: 637 | CF1: 638 | CG1: 639 | CH1: 640 | CI1: 641 | CJ1: 642 | CK1: 643 | CL1: 644 | CM1: 645 | CN1: 646 | CO1: 647 | CP1: 648 | CQ1: 649 | CR1: 650 | CS1: 651 | CT1: 652 | CU1: 653 | CV1: 654 | CW1: 655 | CX1: 656 | CY1: 657 | CZ1: 658 | DA1: 659 | DB1: 660 | DC1: 661 | DD1: 662 | DE1: 663 | DF1: 664 | DG1: 665 | DH1: 666 | DI1: 667 | DJ1: 668 | DK1: 669 | DL1: 670 | DM1: 671 | DN1: 672 | DO1: 673 | DP1: 674 | DQ1: 675 | DR1: 676 | DS1: 677 | DT1: 678 | DU1: 711 | DV1: 712 | DW1: 713 | DX1: 714 | DY1: 715 | DZ1: 716 | EA1: 717 | EB1: 718 | EC1: 719 | ED1: 720 | EE1: 721 | EF1: 722 | EG1: 723 | EH1: 724 | EI1: 725 | EJ1: 726 | EK1: 727 | EL1: 728 | EM1: 729 | EN1: 730 | EO1: 731 | EP1: 732 | EQ1: 733 | ER1: 734 | ES1: 735 | ET1: 736 | EU1: 737 | EV1: 738 | EW1: 739 | EX1: 740 | EY1: 741 | EZ1: 742 | FA1: 743 | FB1: 744 | FC1: 745 | FD1: 746 | FE1: 747 | FF1: 748 | FG1: 749 | FH1: 750 | FI1: 751 | FJ1: 752 | FK1: 753 | FL1: 754 | FM1: 755 | FN1: 820 | FO1: 821 | FP1: 822 | FQ1: 823 | FR1: 824 | FS1: 825 | FT1: 826 | FU1: 827 | FV1: 828 | FW1: 829 | FX1: 830 | FY1: 831 | FZ1: 832 | GA1: 833 | GB1: 834 | GC1: 835 | GD1: 836 | GE1: 837 | GF1: 838 | GG1: 839 | GH1: 840 | GI1: 841 | GJ1: 842 | GK1: 843 | GL1: 844 | GM1: 845 | GN1: 846 | GO1: 847 | GP1: 848 | GQ1: 849 | GR1: 850 | GS1: 851 | GT1: 852 | GU1: 853 | GV1: 854 | GW1: 855 | GX1: 856 | GY1: 857 | GZ1: 858 | HA1: 859 | HB1: 860 | HC1: 861 | HD1: 862 | HE1: 863 | HF1: 864 | HG1: 865 | HH1: 866 | HI1: 867 | HJ1: 868 | HK1: 869 | HL1: 870 | HM1: =((DW1/LY1)/(BA1/DX1))^0.3*(CA1/IB1)/(BA1/CA1) -> 1.0470267 | HN1: 687 | HO1: 688 | HP1: 689 | HQ1: 690 | HR1: 691 | HS1: 692 | HT1: 693 | HU1: 694 | HV1: 695 | HW1: 696 | HX1: 697 | HY1: 698 | HZ1: 699 | IA1: 700 | IB1: 701 | IC1: 702 | ID1: 703 | IE1: 704 | IF1: 705 | IG1: 706 | IH1: 707 | II1: 708 | IJ1: 709 | IK1: 710 | IL1: 711 | IM1: 712 | IN1: 727 | IO1: 728 | IP1: 729 | IQ1: 730 | IR1: 731 | IS1: 732 | IT1: 733 | IU1: 734 | IV1: 735 | IW1: 736 | IX1: 737 | IY1: 738 | IZ1: 739 | JA1: 740 | JB1: 741 | JC1: 742 | JD1: 743 | JE1: 744 | JF1: 745 | JG1: 746 | JH1: 747 | JI1: 748 | JJ1: 749 | JK1: 750 | JL1: 751 | JM1: 752 | JN1: 753 | JO1: 754 | JP1: 755 | JQ1: 756 | JR1: 757 | JS1: 758 | JT1: 759 | JU1: 760 | JV1: 761 | JW1: 762 | JX1: 763 | JY1: 764 | JZ1: 765 | KA1: 766 | KB1: 767 | KC1: 768 | KD1: 769 | KE1: 770 | KF1: 771 | KG1: 772 | KH1: 773 | KI1: 774 | KJ1: 775 | KK1: 776 | KL1: 777 | KM1: 778 | KN1: 779 | KO1: 780 | KP1: 781 | KQ1: 782 | KR1: 783 | KS1: 784 | KT1: 785 | KU1: 786 | KV1: 787 | KW1: 788 | KX1: 789 | KY1: 790 | KZ1: 791 | LA1: 792 | LB1: 793 | LC1: 794 | LD1: 795 | LE1: 796 | LF1: 797 | LG1: 798 | LH1: 799 | LI1: 800 | LJ1: 801 | LK1: 802 | LL1: 803 | LM1: 804 | LN1: 805 | LO1: 806 | LP1: 807 | LQ1: 808 | LR1: 809 | LS1: 810 | LT1: 811 | LU1: 812 | LV1: 813 | LW1: 814 | LX1: 815 | LY1: 816 | LZ1: 817 | MA1: 818 | MB1: 819 | MC1: 820 | MD1: 821 | ME1: 822 | MF1: 823 | MG1: 824 | MH1: 825 | MI1: 826 | MJ1: 827 | MK1: 828 | ML1: 829 | MM1: 830 | MN1: 831 | MO1: 832 | MP1: 833 | MQ1: 834 | MR1: 835 | MS1: 836 | MT1: 837 | MU1: 838 | MV1: 839 | MW1: 840 | MX1: 841 | MY1: 842 | MZ1: 843 | NA1: 844 | NB1: 845 | NC1: 846 | ND1: 847 | NE1: 848 | NF1: 849 | NG1: 850 | NH1: 851 | NI1: 852 | NJ1: 853 | NK1: 854 | NL1: 855 | NM1: 856 | NN1: 857 | NO1: 858 | NP1: 859 | NQ1: 860 | NR1: 861 | NS1: 862 | NT1: 863 | NU1: 864 | NV1: 865 | NW1: 866 | NX1: 867 | NY1: 868 | NZ1: 869 | OA1: 870 | OB1: 871 | OC1: 872 | OD1: 873 | OE1: 874 | OF1: 875 | OG1: 876 | OH1: 877 | OI1: 878 | OJ1: 879 | OK1: 880 | OL1: 881 | OM1: 882 | ON1: 883 | OO1: 884 | OP1: 885 | OQ1: 886 | OR1: 887 | OS1: 888 | OT1: 889 | OU1: 890 | OV1: 891 | OW1: 892 | OX1: 893 | OY1: 894 | OZ1: 895 | PA1: 896 | PB1: 897 | PC1: 898 | PD1: 899 | PE1: 900 | PF1: Simulated SPM Rrs | PH1: Orignial
